Workbook

Sheet Dashboard
A1: Income Expense
A2: Income | C2: Expense | G2: Different Foundation of club Members
A3: Particular | B3: Amount | C3: Particular | D3: Amount | E3: Remarks | F3: Date | G3: Foundation | H3: Balance | I3: Bank/Finance | J3: Annual Interest | K3: Utilization
A4: Membership | B4: ='Membership dues'!C63 -> 273500 | C4: RI Dues | G4: Late Khadgajeet Baral Rotary Food Bank | H4: 1000000 | I4: Shree | J4: =H4*11% -> 110000
A5: Souvenier | B5: ='Souvenier advertisement'!E39 -> 160000 | C5: District Dues | G5: Late Anangam Raj Timalsina Foundation | H5: 700000 | I5: Shree | J5: =H5*11% -> 77000
A6: Service Project | B6: ='Service projects'!C23+'Service projects'!C36 -> 277000 | C6: TRF | G6: Chuman Jung Shahi Rotary Foundation | H6: 100000 | I6: Shree | J6: =H6*11% -> 11000
A7: TRF | B7: =TRF!B51 -> 360 | C7: Rotarct Law Campus | G7: Late Fulchand Kejriwal & Late Gitadevi Memorial Foudation | H7: 150000 | I7: Shree | J7: =H7*11% -> 16500
A8: Smile a while | B8: ='Smile a wile'!D51 -> 15808 | C8: Rotaract Pashupati | D8: 35000 | E8: Installation | F8: 45850 | G8: Late Kul Pradip Subedi and Late Bhima Devi Subedi Rotary Cancer Care Foundation | H8: 500000 | I8: due | J8: =H8*11% -> 55000
A9: Members Contribution | C9: Service project | J9: =H9*11% -> 0
A10: Interest | B10: =J20 -> 269500 | J10: =H10*11% -> 0
A11: Installation | B11: ='Membership dues'!E63 -> 82500 | J11: =H11*11% -> 0
J12: =H12*11% -> 0
J13: =H13*11% -> 0
J14: =H14*11% -> 0
J15: =H15*11% -> 0
J16: =H16*11% -> 0
J17: =H17*11% -> 0
J18: =H18*11% -> 0
J19: =H19*11% -> 0
H20: =SUM(H4:H19) -> 2450000 | J20: =SUM(J4:J19) -> 269500
I21: Years
I22: 2 | J22: =I22*J20 -> 539000
G23: Kept at shree investment for 6yrs with 11% interest rate
G24: starting from PP Rtn, Surya Bdr Adhikari tenure

Sheet Members in a Club Detail
A1: Member ID | B1: Full Name | C1: Gender | D1: Age Bracket | E1: Club Admit Date | F1: Online Account with My Rotary | G1: Email Address | H1: Phone
A2: 11737537 | B2: Nisha Acharya | C2: Not Given | D2: 40 - 49 | E2: 45042 | F2: Not Registered | G2: trackoncouriers15@gmail.com
A3: 12180438 | B3: Raj Kumar Acharya | C3: Male | D3: 40 - 49 | E3: 45585 | F3: Registered | G3: rajkumaracharya11111@gmail.com | H3: 9851131750
A4: 8530082 | B4: Shalik Ram Adhikari | C4: Male | D4: 50 - 59 | E4: 41105 | F4: Registered | G4: shalik.adhikari2018@gmail.com | H4: 9851069257
A5: 9600732 | B5: Surya Bahadur Adhikari | C5: Male | D5: 40 - 49 | E5: 42508 | F5: Registered | G5: surya59219@gmail.com | H5: 9851059219
A6: 6007108 | B6: Kim J. Baaden | C6: Male | D6: Unreported | E6: 40359 | F6: Registered | G6: rotarykim@gmail.com | H6: 985-1087234
A7: 10642646 | B7: Dipendra Banskota | C7: Male | D7: 30 - 39 | E7: 43679 | F7: Registered | G7: sampanna.capital@gmail.com | H7: 9851197327
A8: 11210429 | B8: Dr. Sangeeta Baral Basnet | C8: Female | D8: 50 - 59 | E8: 45345 | F8: Not Registered | G8: sangsbbasnet812@gmail.com | H8: 9851122090
A9: 12199248 | B9: suman Basnet | C9: Male | D9: 40 - 49 | E9: 45611 | F9: Registered | G9: basnetsuman847@gmail.com | H9: 9851131506
A10: 5782750 | B10: Hari Bhakta Budathoki | C10: Male | D10: Unreported | E10: 37437 | F10: Registered | G10: haribhakta@wlink.com.np | H10: 01-4443017
A11: 10827423 | B11: Mina Budhathoki | C11: Female | D11: Unreported | E11: 43896 | F11: Not Registered
A12: 5782751 | B12: Jas Maya Chemjong | C12: Female | D12: Unreported | E12: 37437 | F12: Registered | G12: rtnjessica27@gmail.com | H12: 4275993
A13: 11210423 | B13: Dr. Pravesh Dahal | C13: Male | D13: 30 - 39 | E13: 44409 | F13: Registered | G13: dhl.pravesh@yahoo.com | H13: 9812113206
A14: 11210419 | B14: Dr. Binod Dangal | C14: Male | D14: 40 - 49 | E14: 44409 | F14: Registered | G14: binod.dangal999@gmail.com | H14: 9841715973
A15: 8609992 | B15: Mr Gopal Prasad Dangal | C15: Male | D15: 50 - 59 | E15: 45520 | F15: Registered | G15: dangalgopal1974@gmail.com
A16: 10298957 | B16: Mr Bhupendra Kumar Ghimire | C16: Male | D16: 50 - 59 | E16: 43264 | F16: Registered | G16: vinnepal@gmail.com | H16: 9851070477
A17: 9600730 | B17: Bindu Prakash Joshi | C17: Male | D17: 60 - 69 | E17: 42508 | F17: Registered | G17: bindujoshi163@gmail.com | H17: 9851098796
A18: 12300493 | B18: Dr Archana K C | C18: Female | D18: 30 - 39 | E18: 45748 | F18: Not Registered | G18: kcarchana0511@gmail.com | H18: 9841544615
A19: 10298995 | B19: Er. Milan Kumar K C | C19: Male | D19: 30 - 39 | E19: 43264 | F19: Registered | G19: rtn.milan@gmail.com | H19: 9841634579
A20: 10966814 | B20: Bandana Khanal | C20: Female | D20: 40 - 49 | E20: 44056 | F20: Not Registered | G20: bandana.khanal12@gmail.com
A21: 9627379 | B21: Giri Raj Khatri | C21: Male | D21: 30 - 39 | E21: 44378 | F21: Not Registered | G21: giri.envfrnd@gmail.com
A22: 9322679 | B22: Mr Bhuvan Singh Kunwar | C22: Male | D22: 40 - 49 | E22: 42193 | F22: Registered | G22: 4process2@gmail.com | H22: 9851157230
A23: 9326313 | B23: Mrs Sajal Maskey | C23: Female | D23: 40 - 49 | E23: 45436 | F23: Registered | G23: Sajal.maskey@gmail.com | H23: 9841509412
A24: 10827422 | B24: Deepa Neupane | C24: Female | D24: Unreported | E24: 43896 | F24: Not Registered
A25: 10940408 | B25: Kedar Prasad Neupane | C25: Not Given | D25: Unreported | E25: 41105 | F25: Not Registered
A26: 8214328 | B26: Rajesh Neupane | C26: Male | D26: 70 and over | E26: 40359 | F26: Registered | G26: rajeshneupane516@gmail.com | H26: 9851115433
A27: 10298988 | B27: Mr. Yogendra Ojha | C27: Male | D27: Unreported | E27: 43264 | F27: Registered | G27: ysojha@yahoo.com
A28: 3350066 | B28: Sashi Raj Pandey | C28: Male | D28: 70 and over | E28: 44006 | F28: Registered | G28: sashipandey@gmail.com | H28: 9851104403
A29: 11210412 | B29: Urmila Pandey | C29: Female | D29: 70 and over | E29: 44409 | F29: Registered | G29: urupandey@gmail.com | H29: 9851107118
A30: 12214799 | B30: Ramu Pandeya | C30: Male | D30: 30 - 39 | E30: 45604 | F30: Registered | G30: ramupandeya2000@gmail.com | H30: 9851070954
A31: 8119900 | B31: Khem Raj Panta | C31: Male | D31: 40 - 49 | E31: 45379 | F31: Registered | G31: khempanta@hotmail.com | H31: 9851021876
A32: 10406678 | B32: Mr Manoj Paudel | C32: Male | D32: 30 - 39 | E32: 45336 | F32: Registered | G32: rtnmanoj27@gmail.com
A33: 10908625 | B33: Mr. Moti Ram Phuyal | C33: Male | D33: Unreported | E33: 43983 | F33: Not Registered
A34: 5978850 | B34: Gopal Prasad Pokhrel | C34: Male | D34: Unreported | E34: 39330 | F34: Registered | G34: Pokhrelg19@gmail.com | H34: 14821518
A35: 11553763 | B35: Mr Purna Bahadur Rai | C35: Male | D35: 70 and over | E35: 44789 | F35: Not Registered | G35: md@rajoverseas.com | H35: 9851020787
A36: 11789085 | B36: Mrs Mamta Raj Singh | C36: Female | D36: 40 - 49 | E36: 45078 | F36: Not Registered | G36: mamataforus@gmail.com | H36: 9841278126
A37: 8098718 | B37: Bhubaneshwori Rao | C37: Female | D37: 50 - 59 | E37: 45336 | F37: Registered | G37: bhuvna12@hotmail.com | H37: 9851105564
A38: 3349942 | B38: Min Bahadur Raut | C38: Male | D38: Unreported | E38: 39820 | F38: Not Registered | G38: minraut@ntc.net.up
A39: 10994233 | B39: Shristi Raut | C39: Female | D39: 29 and under | E39: 45486 | F39: Registered | G39: rautsristy22@gmail.com | H39: 9843987930
A40: 3350010 | B40: Devendra Rijal | C40: Male | D40: Unreported | E40: 35886 | F40: Not Registered | G40: devprijal@wlink.com.np | H40: 4466999/4470960
...

Sheet Membership dues
B1: Membership Dues Payment RY 2025/26
A2: SN | B2: Full Name | C2: Dues | D2: TRF(25$) | E2: Installation Charge | F2: Remarks | G2: Date
A3: 1 | B3: Nisha Acharya | E3: 2500 | F3: QR
A4: =A3+1 -> 2 | B4: Raj Kumar Acharya | C4: 25000 | F4: FP Prime | G4: 29 June,25
A5: =A4+1 -> 3 | B5: Shalik Ram Adhikari | C5: 25000 | E5: 2500 | F5: chq
A6: =A5+1 -> 4 | B6: Surya Bahadur Adhikari | C6: 25000 | D6: 3500 | E6: 2500 | F6: FP prime | G6: 8th july
A7: =A6+1 -> 5 | B7: Kim J. Baaden
A8: =A7+1 -> 6 | B8: Dipendra Banskota
A9: =A8+1 -> 7 | B9: Dr. Sangeeta Baral Basnet
A10: =A9+1 -> 8 | B10: suman Basnet
A11: =A10+1 -> 9 | B11: Hari Bhakta Budathoki | C11: 25000 | D11: 13000 | E11: 7500 | F11: Cash/Deposit Prime | G11: 2nd July
A12: =A11+1 -> 10 | B12: Mina Budhathoki | C12: 25000 | D12: 13000 | F12: Cash/Deposit Prime | G12: 2nd July
A13: =A12+1 -> 11 | B13: Jas Maya Chemjong | E13: 7500 | F13: Cash/Deposit Prime
A14: =A13+1 -> 12 | B14: Dr. Pravesh Dahal | E14: 2500 | F14: Cash/Deposit Prime
A15: =A14+1 -> 13 | B15: Dr. Binod Dangal | E15: 2500 | F15: QR
A16: =A15+1 -> 14 | B16: Mr Gopal Prasad Dangal
A17: =A16+1 -> 15 | B17: Mr Bhupendra Kumar Ghimire | E17: 2500
A18: =A17+1 -> 16 | B18: Bindu Prakash Joshi | E18: 2500
A19: =A18+1 -> 17 | B19: Dr Archana K C | C19: 25000 | D19: 3500 | E19: 2500 | F19: FP prime | G19: 8th July
A20: =A19+1 -> 18 | B20: Er. Milan Kumar K C | H20: 4
A21: =A20+1 -> 19 | B21: Bandana Khanal
A22: =A21+1 -> 20 | B22: Giri Raj Khatri
A23: =A22+1 -> 21 | B23: Mr Bhuvan Singh Kunwar | E23: 2500
A24: =A23+1 -> 22 | B24: Mrs Sajal Maskey
A25: =A24+1 -> 23 | B25: Deepa Neupane
A26: =A25+1 -> 24 | B26: Kedar Prasad Neupane
A27: =A26+1 -> 25 | B27: Rajesh Neupane | E27: 10000
A28: =A27+1 -> 26 | B28: Mr. Yogendra Ojha
A29: =A28+1 -> 27 | B29: Sashi Raj Pandey
A30: =A29+1 -> 28 | B30: Urmila Pandey
A31: =A30+1 -> 29 | B31: Ramu Pandeya | E31: 2500
A32: =A31+1 -> 30 | B32: Khem Raj Panta
A33: =A32+1 -> 31 | B33: Mr Manoj Paudel | E33: 2500
A34: =A33+1 -> 32 | B34: Mr. Moti Ram Phuyal | C34: 25000 | D34: 3500 | E34: 2500 | F34: FP prime | G34: 8th july
A35: =A34+1 -> 33 | B35: Gopal Prasad Pokhrel
A36: =A35+1 -> 34 | B36: Mr Purna Bahadur Rai
A37: =A36+1 -> 35 | B37: Mrs Mamta Raj Singh | H37: 2
A38: =A37+1 -> 36 | B38: Bhubaneshwori Rao
A39: =A38+1 -> 37 | B39: Min Bahadur Raut
A40: =A39+1 -> 38 | B40: Shristi Raut | C40: 13500 | D40: 3500 | E40: 2500 | F40: FP Prime | G40: 2nd July
...

Sheet Sheet1
A1: 28th Installation Ceremony, Rotary Club of Pashupati
A2: Guest from Distrct and Rotary Club
A3: SN | B3: Name | C3: Designation | D3: Contact no | E3: Home club/District | F3: Signature
A4: 1
A5: =A4+1 -> 2
A6: =A5+1 -> 3
A7: =A6+1 -> 4
A8: =A7+1 -> 5
A9: =A8+1 -> 6
A10: =A9+1 -> 7
A11: =A10+1 -> 8
A12: =A11+1 -> 9
A13: =A12+1 -> 10
A14: =A13+1 -> 11
A15: =A14+1 -> 12
A16: =A15+1 -> 13
... A34: =A33+1 -> 31
A35: Guest from Rotaract Club
A36: SN | B36: Name | C36: Designation | D36: Contact no | E36: Home club/District | F36: Signature
A37: 1
A38: =A37+1 -> 2
A39: =A38+1 -> 3
A40: =A39+1 -> 4
A41: =A40+1 -> 5
A42: =A41+1 -> 6
A43: =A42+1 -> 7
A44: =A43+1 -> 8
A45: =A44+1 -> 9
A46: =A45+1 -> 10
A47: =A46+1 -> 11
A48: =A47+1 -> 12
A49: =A48+1 -> 13
... A51: =A50+1 -> 15

Sheet Attendance-weekly (2)
A1: Rotary Club of Pashupati Kathmandu
A2: Board Meeting Attendance
A3: SN | C3: Meeting No: | D3: Date:
C4: Time: | D4: Venue:
B5: Name | C5: Member | D5: Designation | E5: Signature
A6: 1 | B6: Ganesh Subedi | C6: ="Rtn."&B6 -> Rtn.Ganesh Subedi | D6: President
A7: =A6+1 -> 2 | B7: Milan Kumar KC | C7: ="Rtn."&B7 -> Rtn.Milan Kumar KC | D7: Immediate Past President
A8: =A7+1 -> 3 | B8: Bindu Prakash Joshi | C8: ="Rtn."&B8 -> Rtn.Bindu Prakash Joshi | D8: President Elect
A9: =A8+1 -> 4 | B9: Dipendra Baskota | C9: ="Rtn."&B9 -> Rtn.Dipendra Baskota | D9: President Nominee
A10: =A9+1 -> 5 | B10: Tej Prasad Timalsina | C10: ="Rtn."&B10 -> Rtn.Tej Prasad Timalsina | D10: Vice President
A11: =A10+1 -> 6 | B11: Dr Pravesh Dahal | C11: ="Rtn."&B11 -> Rtn.Dr Pravesh Dahal | D11: Vice President
A12: =A11+1 -> 7 | B12: Manoj Paudel | C12: ="Rtn."&B12 -> Rtn.Manoj Paudel | D12: Secretary
A13: =A12+1 -> 8 | B13: Nisha Acharya | C13: ="Rtn."&B13 -> Rtn.Nisha Acharya | D13: Treasurer
A14: =A13+1 -> 9 | B14: Chumban Jung Shahi | C14: ="Rtn."&B14 -> Rtn.Chumban Jung Shahi | D14: PP/Sergent At Arms
A15: =A14+1 -> 10 | B15: Ramu Pandeya | C15: ="Rtn."&B15 -> Rtn.Ramu Pandeya | D15: Club Admin Chair
A16: =A15+1 -> 11 | B16: Hark Saud | C16: ="Rtn."&B16 -> Rtn.Hark Saud | D16: PP/Service Project Chair
A17: =A16+1 -> 12 | B17: Surya Bahadur Adhikari | C17: ="Rtn."&B17 -> Rtn.Surya Bahadur Adhikari | D17: PP/The Rotary Foundation Chair
A18: =A17+1 -> 13 | B18: Dr Motiram Phuyal | C18: ="Rtn."&B18 -> Rtn.Dr Motiram Phuyal | D18: Membership Chair
... A28: =A27+1 -> 23 | B28: Dr Archana KC | C28: ="Rtn."&B28 -> Rtn.Dr Archana KC | D28: Service Project Co Chair
A29: =A28+1 -> 24 | C29: Rtn.Gopal Pokharel | D29: Past President/AG
A30: =A29+1 -> 25
A31: =A30+1 -> 26
A32: =A31+1 -> 27
A33: =A32+1 -> 28
A34: =A33+1 -> 29
A35: =A34+1 -> 30
A36: =A35+1 -> 31
A37: =A36+1 -> 32
A38: =A37+1 -> 33
A39: =A38+1 -> 34
A40: =A39+1 -> 35
A41: =A40+1 -> 36
... A61: =A60+1 -> 56
C62: Guest Member from Rotary Club/Other Organization
A63: SN | C63: Name | D63: Rotary club/Org/Designation | E63: Signature
A64: 1
A65: =A64+1 -> 2
A66: =A65+1 -> 3
A67: =A66+1 -> 4
A68: =A67+1 -> 5
...

Sheet Attendance-weekly
A1: Rotary Club of Pashupati Kathmandu
A2: Weekly Meeting Attendance
A3: SN | C3: Meeting No: | D3: Date:
C4: Time: | D4: Venue:
B5: Name | C5: Member | D5: Designation | E5: Signature
A6: 1 | B6: Ganesh Subedi | C6: ="Rtn."&B6 -> Rtn.Ganesh Subedi | D6: President
A7: =A6+1 -> 2 | B7: Milan Kumar KC | C7: ="Rtn."&B7 -> Rtn.Milan Kumar KC | D7: Immediate Past President
A8: =A7+1 -> 3 | B8: Bindu Prakash Joshi | C8: ="Rtn."&B8 -> Rtn.Bindu Prakash Joshi | D8: President Elect
A9: =A8+1 -> 4 | B9: Dipendra Baskota | C9: ="Rtn."&B9 -> Rtn.Dipendra Baskota | D9: President Nominee
A10: =A9+1 -> 5 | B10: Tej Prasad Timalsina | C10: ="Rtn."&B10 -> Rtn.Tej Prasad Timalsina | D10: Vice President
A11: =A10+1 -> 6 | B11: Dr Pravesh Dahal | C11: ="Rtn."&B11 -> Rtn.Dr Pravesh Dahal | D11: Vice President
A12: =A11+1 -> 7 | B12: Manoj Paudel | C12: ="Rtn."&B12 -> Rtn.Manoj Paudel | D12: Secretary
A13: =A12+1 -> 8 | B13: Nisha Acharya | C13: ="Rtn."&B13 -> Rtn.Nisha Acharya | D13: Treasurer
A14: =A13+1 -> 9 | B14: Chumban Jung Shahi | C14: ="Rtn."&B14 -> Rtn.Chumban Jung Shahi | D14: PP/Sergent At Arms
A15: =A14+1 -> 10 | B15: Ramu Pandeya | C15: ="Rtn."&B15 -> Rtn.Ramu Pandeya | D15: Club Admin Chair
A16: =A15+1 -> 11 | B16: Hark Saud | C16: ="Rtn."&B16 -> Rtn.Hark Saud | D16: PP/Service Project Chair
A17: =A16+1 -> 12 | B17: Surya Bahadur Adhikari | C17: ="Rtn."&B17 -> Rtn.Surya Bahadur Adhikari | D17: PP/The Rotary Foundation Chair
A18: =A17+1 -> 13 | B18: Dr Motiram Phuyal | C18: ="Rtn."&B18 -> Rtn.Dr Motiram Phuyal | D18: Membership Chair
... A28: =A27+1 -> 23 | B28: Dr Archana KC | C28: ="Rtn."&B28 -> Rtn.Dr Archana KC | D28: Service Project Co Chair
A29: =A28+1 -> 24 | C29: Rtn.Gopal Pokharel | D29: Past President/AG
A30: =A29+1 -> 25
A31: =A30+1 -> 26
A32: =A31+1 -> 27
A33: =A32+1 -> 28
A34: =A33+1 -> 29
A35: =A34+1 -> 30
A36: =A35+1 -> 31
A37: =A36+1 -> 32
A38: =A37+1 -> 33
A39: =A38+1 -> 34
A40: =A39+1 -> 35
A41: =A40+1 -> 36
... A61: =A60+1 -> 56
C62: Guest Member from Rotary Club/Other Organization
A63: SN | C63: Name | D63: Rotary club/Org/Designation | E63: Signature
A64: 1
A65: =A64+1 -> 2
A66: =A65+1 -> 3
A67: =A66+1 -> 4
A68: =A67+1 -> 5
...

Sheet Expense
A1: Rotary Club of Pashupati Kathmandu
A2: Expense details
A4: SN | B4: Particular | C4: Amount | D4: payment | E4: remarks | F4: Received
A5: 1 | B5: Food donation | C5: 50290 | D5: chq | E5: Manoj | F5: Chq 144010
A6: 2 | B6: Thanka | C6: 19800 | D6: chq | E6: Manoj
A7: 3 | B7: Surgical item | C7: 25870 | D7: Chq | E7: Manoj
A8: 4 | B8: Installation various-rohan expense | C8: 13550 | D8: chq | E8: Manoj
A9: 5 | B9: Liquor installation | C9: 34500 | D9: chq | E9: Manoj
A10: 6 | B10: Mental hospital banner | C10: 450 | E10: Manoj | F10: due
A11: 7 | B11: Mental hospital Inaugural cloth | C11: 300 | E11: Manoj | F11: due
A12: 8 | B12: Birthday cake | C12: =7000+2290 -> 9290 | D12: Chq | E12: Manoj | F12: Chq 76290
A13: 9 | B13: Mental hospital metal plate | C13: 14000 | D13: chq | E13: Manoj
A14: 10 | B14: Samman patra metal IPP | C14: 3000 | D14: chq | E14: Manoj
A15: 11 | B15: Tree plantation kageshwari | C15: 50000 | D15: chq | E15: Manoj
A16: 12 | B16: Tree Plantation Banner | C16: 2000 | E16: Manoj | F16: due
A17: 13 | B17: Mohar ticket print | C17: 2250 | E17: Manoj | F17: due
A18: 14 | B18: Food donation vehicle | C18: 1500 | E18: Harka dai | F18: due
A19: 14 | B19: Token of love-2 | C19: 2000 | E19: Harka dai | F19: due
A20: 15 | B20: Receipt print | C20: 1500 | E20: Manoj | F20: due
A21: 16 | B21: Water filter project | C21: 275000 | E21: Vendor | F21: chq 275000
A22: 17 | B22: Photographer Installation | C22: 18000 | E22: Manoj | F22: chq 18000
C23: =SUM(C5:C22) -> 523300

Sheet Souvenier advertisement
A1: Souvenier Advertisement
A2: SN | B2: Company | C2: Focal person | D2: Amount | E2: Payment | F2: Remarks
A3: 1 | B3: Marron Group | C3: Rtn. Ganesh | D3: 30000
A4: 2 | B4: India | C4: Rtn. Ganesh | D4: 30000 | E4: 30000 | F4: Manoj
A5: 3 | B5: India | C5: Rtn. Ganesh | D5: 30000 | E5: 30000 | F5: Manoj
A6: 4 | B6: India | C6: Rtn. Ganesh | D6: 40000 | E6: 40000 | F6: Manoj
A7: 5 | B7: India | C7: Rtn. Ganesh | D7: 40000 | E7: 40000 | F7: Manoj
A8: 6 | B8: Sanima Bank | C8: Rtn. Ganesh | D8: 30000
A9: 7 | B9: Apex World wide express | C9: Rtn. Durga | D9: 30000
A10: 8 | B10: Mohar | C10: Rtn Chumanjung | D10: 30000
A11: 9 | B11: St josep School | C11: Rtn Surya | D11: 30000
A12: 10 | B12: Enfrontwheel | C12: Rtn Himalaya | D12: 5000
A13: 11 | B13: Haribhakta sir | C13: Rtn Haribhakta | D13: 10000
A14: 12 | B14: Rajesh Neupane sir | C14: Rtn Rajesh | D14: 10000
A15: 13 | B15: New Arunodaya School | C15: Rtn Jessica | D15: 10000
A16: 14 | B16: DAV School | C16: Rtn Bhubanesowri | D16: 10000
A17: 15 | B17: Sushma Koirala | C17: Rtn Mamta | D17: 20000
A18: 16 | B18: Shree Investment | C18: Rtn Sashi | D18: 20000 | E18: 20000 | F18: Prime Ac
A19: 17 | B19: Hotel Soaltee | C19: Rtn Sashi | D19: 10000
A20: 18 | B20: Leapfrog | C20: Rtn Sashi | D20: 40000
A21: 19 | B21: Hotel Crown Imperial | C21: Rtn Sajal | D21: 5000
A22: 20 | B22: Asian Life Insurance | C22: Rtn Sajal | D22: 10000
A23: 21 | B23: Oxford Securities | C23: Rtn Ganesh | D23: 15000
A24: 22 | B24: Kumari Securities | C24: Rtn Shalik | D24: 10000
A25: 23 | B25: Best Wishes | C25: Rtn Motiram | D25: 5000
A26: 24 | B26: Best Wishes | C26: Rtn Tej | D26: 5000
A27: 25 | B27: DIamond crushing | C27: Rtn Ganesh | D27: 40000
A28: 26 | B28: Natioanl Insurance | C28: Rtn Sajal | D28: 10000
A29: 27 | B29: Best wishes Gahatraj | C29: Rtn Ganesh | D29: 30000
A30: 28 | B30: Best wishes BIplav | C30: Rtn Ganesh | D30: 15000
... A33: 31 | B33: Best wishes Rtn Prakash | C33: RTn prakash | D33: 5000
D39: =SUM(D3:D38) -> 590000 | E39: =SUM(E3:E38) -> 160000

Sheet TRF
A1: TRF Contribution RY 2025/26
A2: Name | B2: Amount $ | C2: For | D2: Commitment | E2: Remarks | F2: Date
A3: Rtn. Sashi Raj Pandey | C3: Polio Plus | D3: 10000
A4: Rtn. Haribhakta Budhathoki | B4: 100 | C4: Polioplus/Annual Fund | E4: Cash/deposit prime | F4: 2nd July
A5: Rtn Rajesh Neupane | C5: Polioplus/Annual Fund | D5: 200
A6: Rtn Deepa Neupane | C6: Polioplus/Annual Fund | D6: 200
A7: Rtn Kedar Neupane | C7: Polioplus/Annual Fund | D7: 200
A8: Rtn Shristi Raut | B8: 25 | C8: Annual Fund | E8: FP prime | F8: 2nd July
A9: Rtn Chumanjung Shahi | B9: 35 | C9: Annual Fund | E9: FP prime | F9: 2nd July
A10: Rtn Mina Budhathoki | B10: 100 | C10: Annual Fund | E10: Cash/deposit prime | F10: 2nd July
A11: Rtn Durga Subedi | C11: MD2 | D11: 9000
A12: Rtn Ganesh Subedi | C12: PHS | D12: 1000
A13: Rtn Dr Archana Kc | B13: 25 | C13: Annual fund | E13: FP prime | F13: 8th July
A14: Rtn Motiram Phuyal | B14: 25 | C14: Annual Fund | E14: FP prime | F14: 8th July
A15: Rtn Surya Bahadur Adhikari | B15: 25 | C15: Annual Fund | E15: FP prime | F15: 8th July
A16: Rtn Himalaya Dev Sigdel | B16: 25 | C16: Annual Fund | E16: Cash/deposit prime | F16: 18th July
A17: Rtn Shalik Ram ahikari | C17: Annual Fund | D17: 3000
B51: =SUM(B3:B50) -> 360 | D51: =SUM(D3:D50) -> 23600

Sheet Smile a wile
B1: Smile a wile
A2: Date | B2: Cash | C2: FP Prime | D2: Total
A3: 2nd July 2025 | B3: =D3-C3 -> 9600 | C3: 6208 | D3: 15808
D51: =SUM(D3:D50) -> 15808

Sheet Service projects
A1: Water treatment plant( Mental Hospital Patan)
A2: Name | B2: Commitment | C2: Payment | D2: Remarks
A3: Rtn Ganesh Subedi | B3: 100000 | C3: 100000 | D3: FP Prime
A4: Rtn Surya Bahadur Adhikari | B4: 20000
A5: Rtn Rajesh/Rtn Deepa/Rtn Kedar | B5: 15000 | C5: 15000 | D5: FP Prime
A6: Rtn Chuman Jung Shahi | B6: 15000
A7: Rtn Hari Bhakta Budhathoki/Rtn Mina | B7: 15000 | C7: 15000 | D7: FP Prime
A8: Rtn Sashi/Urmila/Suswopna | B8: 15000 | C8: 15000 | D8: FP Prime
A9: Rtn Jessica Chemjong | B9: 10000 | C9: 10000
A10: Rtn MIlan Kumar Kc | B10: 10000
A11: Rtn Bindu Prakash Joshi | B11: 10000 | C11: 10000 | D11: FP Prime
A12: Rtn Archana Kc | B12: 10000 | C12: 10000 | D12: FP Prime
A13: Rtn Manoj Paudel | B13: 5000 | C13: 5000 | D13: FP prime
A14: Rtn Mamata Raj Singh | B14: 5000 | C14: 5000 | D14: FP Prime
A15: Rtn Dipendra Banskota | B15: 5000
A16: Rtn Prakash Sapkota | B16: 5000 | C16: 5000 | D16: FP Prime
A17: Rtn Pravesh Dahal | B17: 5000
A18: Rtn Nisha Acharya | B18: 5000
A19: Rtn Motiram Phuyal | B19: 5000
A20: Rtn Ramu Pandeya | B20: 5000 | C20: 5000 | D20: FP Prime
A21: Rtn Tej Prasad Timalsina | B21: 3000 | C21: 3000 | D21: FP Prime
A22: Rtn Shristi Raut | B22: 2500
B23: =SUM(B3:B22) -> 265500 | C23: =SUM(C3:C22) -> 198000
A29: KJ Baral Rotary Food Bank
A30: Rtn Sashi Raj Pandey | C30: 79000
C36: =SUM(C30:C35) -> 79000

Sheet Administrative cost
A1: Administrative Expenses
A2: SN | B2: Particular | C2: Expense | D2: Remarks
A3: 1 | B3: Tshirt
A4: 2 | B4: Diary & Pen

Sheet Miscelleneous
A1: Miscelleneous Expenses and Commitment
A2: Project Name | B2: Name | C2: Commitment | D2: Payment | E2: Remarks
A3: Club T shirt | B3: Rtn Ganesh Subedi
A4: Diary and Pen | B4: Rtn Ganesh Subedi
A5: Rotaract Club Of Pashupati Kathmandu Installation | B5: Rtn Ganesh Subedi | C5: 35000 | D5: 35000 | E5: FP Rotarct A/c
